<?xml version="1.0" ?>
<!-- =================================================================================== -->
<!-- |    This document was autogenerated by xacro from pal.urdf.xacro                 | -->
<!-- |    EDITING THIS FILE BY HAND IS NOT RECOMMENDED                                 | -->
<!-- =================================================================================== -->
<robot name="anubis">
  <link name="base_link">
  	<inertial>
  		<!-- Inertial frame at link origin -->
		<origin xyz="0 0 0" rpy="0 0 0"/>
		<!-- Mass of the base -->
  	<mass value="50"/>
    <inertia ixx="0.001" ixy="0." ixz="0." iyy="0.001" iyz="0." izz="0.001"/>
  	<!-- Moments of inertia about the link frame axes -->
	</inertial>
    <visual>
      <origin xyz="0 0 0" rpy="0 0 0"/>
      <geometry>
        <mesh filename="/root/IsaacLab/anubis/meshes/anubis_base_without_wheel.stl"/>
      </geometry>
      <material name="">
        <color rgba="0.75294 0.75294 0.75294 1"/>
      </material>    
    </visual>
    <collision>
      <origin xyz="0 0 0" rpy="0 0 0"/>
      <geometry>
        <mesh filename="/root/IsaacLab/anubis/meshes/anubis_base_without_wheel.stl"/>
      </geometry>
    </collision>
  </link>

<!-- OmniR","OmniFL","OmniFR -->

  <joint name="OmniR" type="continuous">
    <parent link="base_link"/>
    <child link="OmniR_wheel"/>
    <origin xyz="-0.21 0 0.1" rpy="0 0 0"/>
  </joint>

  <link name="OmniR_wheel">
    <inertial>
  		<!-- Inertial frame at link origin -->
		<origin xyz="0 0 0" rpy="0 0 0"/>
  		<mass value="2.5"/>
      <i10tia ixx="0.001" ixy="0." ixz="0." iyy="0.001" iyz="0." izz="0.001"/>
  		<!-- Moments of inertia about the link frame axes -->
	</inertial>
    <visual>
      <origin xyz="0 0 0" rpy="0 0 0"/>
      <geometry>
        <mesh filename="/root/IsaacLab/anubis/meshes/ow206.stl"/>
      </geometry>
      <material name="">
        <color rgba="0.5 0.5 0.5 1"/>
      </material>    
    </visual>
<!-- Inner cylinder -->
    <collision>
      <origin xyz="0 0 0" rpy="0 1.5708 0"/>
      <geometry>
        <cylinder length="0.05" radius="0.08"/>
      </geometry>
    </collision>
    <!-- Outer cylinder -->
    <collision>
      <origin xyz="0 0 0" rpy="0 1.5708 0"/>
      <geometry>
        <cylinder length="0.05" radius="0.029"/>
      </geometry>
    </collision>
    <!-- Ten spheres as rollers -->
    <!-- Angle step = 36 degrees -->
  </link>

  <!--===============================================================-->
  <!-- ===== 2) BIG ROLLERS (radius = 0.03 m) at α = 0°,36°,…,324° ===== -->
  <!-- R_big_center = 0.065 m.  Outer = 0.065 + 0.03 = 0.095.        -->
  <!--===============================================================-->

  <!-- Big roller 0 (α = 0°:  y=0.065, z=0.000) -->
  <link name="OmniR_roller_0">
    <collision>
      <origin xyz="0 0 0" rpy="0 0 0"/>
      <geometry>
        <sphere radius="0.03"/>
      </geometry>
    </collision>
    <inertial>
      <!-- Example mass/inertia for a uniform sphere of radius 0.03 m. -->
      <mass value="0.5"/>
      <inertia
        ixx="0.0000108" ixy="0.0" ixz="0.0"
        iyy="0.0000108" iyz="0.0"
        izz="0.0000108"/>
    </inertial>
  </link>
  <joint name="OmniR_roller_0_joint" type="continuous">
    <parent link="OmniR_wheel"/>
    <child  link="OmniR_roller_0"/>
    <!-- α =  0° → y = 0.065, z = 0.000 -->
    <origin xyz="0 0.065 0.000" rpy="0 0 0"/>
    <!-- axis = (0, –sin0°, cos0°) = (0, 0, 1) -->
    <axis xyz="0 0 1"/>
  </joint>

  <!-- Big roller 2 (α = 36°:  y = 0.065·cos36° ≈ 0.0526,  z = 0.065·sin36° ≈ 0.0382) -->
  <link name="OmniR_roller_2">
    <collision>
      <origin xyz="0 0 0" rpy="0 0 0"/>
      <geometry>
        <sphere radius="0.03"/>
      </geometry>
    </collision>
    <inertial>
      <mass value="0.5"/>
      <inertia
        ixx="0.0000108" ixy="0.0" ixz="0.0"
        iyy="0.0000108" iyz="0.0"
        izz="0.0000108"/>
    </inertial>
  </link>
  <joint name="OmniR_roller_2_joint" type="continuous">
    <parent link="OmniR_wheel"/>
    <child  link="OmniR_roller_2"/>
    <origin xyz="0 0.0526 0.0382" rpy="0 0 0"/>
    <!-- axis = (0, –sin36°, cos36°) = (0, –0.588, 0.809) -->
    <axis xyz="0 -0.588 0.809"/>
  </joint>

  <!-- Big roller 4 (α = 72°:  y ≈ 0.065·cos72° = 0.0201,  z ≈ 0.065·sin72° = 0.0617) -->
  <link name="OmniR_roller_4">
    <collision>
      <origin xyz="0 0 0" rpy="0 0 0"/>
      <geometry>
        <sphere radius="0.03"/>
      </geometry>
    </collision>
    <inertial>
      <mass value="0.5"/>
      <inertia
        ixx="0.0000108" ixy="0.0" ixz="0.0"
        iyy="0.0000108" iyz="0.0"
        izz="0.0000108"/>
    </inertial>
  </link>
  <joint name="OmniR_roller_4_joint" type="continuous">
    <parent link="OmniR_wheel"/>
    <child  link="OmniR_roller_4"/>
    <origin xyz="0 0.0201 0.0617" rpy="0 0 0"/>
    <!-- axis = (0, –sin72°, cos72°) = (0, –0.951, 0.309) approximated -->
    <axis xyz="0 -0.951 0.309"/>
  </joint>

  <!-- Big roller 6 (α = 108°:  y = 0.065·cos108° ≈ –0.0201,  z = 0.065·sin108° ≈ 0.0617) -->
  <link name="OmniR_roller_6">
    <collision>
      <origin xyz="0 0 0" rpy="0 0 0"/>
      <geometry>
        <sphere radius="0.03"/>
      </geometry>
    </collision>
    <inertial>
      <mass value="0.5"/>
      <inertia
        ixx="0.0000108" ixy="0.0" ixz="0.0"
        iyy="0.0000108" iyz="0.0"
        izz="0.0000108"/>
    </inertial>
  </link>
  <joint name="OmniR_roller_6_joint" type="continuous">
    <parent link="OmniR_wheel"/>
    <child  link="OmniR_roller_6"/>
    <origin xyz="0 -0.0201 0.0617" rpy="0 0 0"/>
    <!-- axis = (0, –sin108°, cos108°) = (0, –0.951, –0.309) -->
    <axis xyz="0 -0.951 -0.309"/>
  </joint>

  <!-- Big roller 8 (α = 144°:  y ≈ –0.0526,  z ≈ 0.0382) -->
  <link name="OmniR_roller_8">
    <collision>
      <origin xyz="0 0 0" rpy="0 0 0"/>
      <geometry>
        <sphere radius="0.03"/>
      </geometry>
    </collision>
    <inertial>
      <mass value="0.5"/>
      <inertia
        ixx="0.0000108" ixy="0.0" ixz="0.0"
        iyy="0.0000108" iyz="0.0"
        izz="0.0000108"/>
    </inertial>
  </link>
  <joint name="OmniR_roller_8_joint" type="continuous">
    <parent link="OmniR_wheel"/>
    <child  link="OmniR_roller_8"/>
    <origin xyz="0 -0.0526 0.0382" rpy="0 0 0"/>
    <!-- axis = (0, –sin144°, cos144°) = (0, –0.588, –0.809) -->
    <axis xyz="0 -0.588 -0.809"/>
  </joint>

  <!-- Big roller 10 (α = 180°:  y = –0.065,  z = 0) -->
  <link name="OmniR_roller_10">
    <collision>
      <origin xyz="0 0 0" rpy="0 0 0"/>
      <geometry>
        <sphere radius="0.03"/>
      </geometry>
    </collision>
    <inertial>
      <mass value="0.5"/>
      <inertia
        ixx="0.0000108" ixy="0.0" ixz="0.0"
        iyy="0.0000108" iyz="0.0"
        izz="0.0000108"/>
    </inertial>
  </link>
  <joint name="OmniR_roller_10_joint" type="continuous">
    <parent link="OmniR_wheel"/>
    <child  link="OmniR_roller_10"/>
    <origin xyz="0 -0.065 0.000" rpy="0 0 0"/>
    <!-- axis = (0, –sin180°, cos180°) = (0, 0, –1) -->
    <axis xyz="0 0 -1"/>
  </joint>

  <!-- Big roller 12 (α = 216°:  y ≈ –0.0526,  z ≈ –0.0382) -->
  <link name="OmniR_roller_12">
    <collision>
      <origin xyz="0 0 0" rpy="0 0 0"/>
      <geometry>
        <sphere radius="0.03"/>
      </geometry>
    </collision>
    <inertial>
      <mass value="0.5"/>
      <inertia
        ixx="0.0000108" ixy="0.0" ixz="0.0"
        iyy="0.0000108" iyz="0.0"
        izz="0.0000108"/>
    </inertial>
  </link>
  <joint name="OmniR_roller_12_joint" type="continuous">
    <parent link="OmniR_wheel"/>
    <child  link="OmniR_roller_12"/>
    <origin xyz="0 -0.0526 -0.0382" rpy="0 0 0"/>
    <!-- axis = (0, –sin216°, cos216°) = (0, 0.588, –0.809) -->
    <axis xyz="0 0.588 -0.809"/>
  </joint>

  <!-- Big roller 14 (α = 252°:  y ≈ –0.0201,  z ≈ –0.0617) -->
  <link name="OmniR_roller_14">
    <collision>
      <origin xyz="0 0 0" rpy="0 0 0"/>
      <geometry>
        <sphere radius="0.03"/>
      </geometry>
    </collision>
    <inertial>
      <mass value="0.5"/>
      <inertia
        ixx="0.0000108" ixy="0.0" ixz="0.0"
        iyy="0.0000108" iyz="0.0"
        izz="0.0000108"/>
    </inertial>
  </link>
  <joint name="OmniR_roller_14_joint" type="continuous">
    <parent link="OmniR_wheel"/>
    <child  link="OmniR_roller_14"/>
    <origin xyz="0 -0.0201 -0.0617" rpy="0 0 0"/>
    <!-- axis = (0, –sin252°, cos252°) = (0, 0.951, –0.309) -->
    <axis xyz="0 0.951 -0.309"/>
  </joint>

  <!-- Big roller 16 (α = 288°:  y ≈ 0.0201,  z ≈ –0.0617) -->
  <link name="OmniR_roller_16">
    <collision>
      <origin xyz="0 0 0" rpy="0 0 0"/>
      <geometry>
        <sphere radius="0.03"/>
      </geometry>
    </collision>
    <inertial>
      <mass value="0.5"/>
      <inertia
        ixx="0.0000108" ixy="0.0" ixz="0.0"
        iyy="0.0000108" iyz="0.0"
        izz="0.0000108"/>
    </inertial>
  </link>
  <joint name="OmniR_roller_16_joint" type="continuous">
    <parent link="OmniR_wheel"/>
    <child  link="OmniR_roller_16"/>
    <origin xyz="0 0.0201 -0.0617" rpy="0 0 0"/>
    <!-- axis = (0, –sin288°, cos288°) = (0, 0.951, 0.309) -->
    <axis xyz="0 0.951 0.309"/>
  </joint>

  <!-- Big roller 18 (α = 324°:  y ≈ 0.0526,  z ≈ –0.0382) -->
  <link name="OmniR_roller_18">
    <collision>
      <origin xyz="0 0 0" rpy="0 0 0"/>
      <geometry>
        <sphere radius="0.03"/>
      </geometry>
    </collision>
    <inertial>
      <mass value="0.5"/>
      <inertia
        ixx="0.0000108" ixy="0.0" ixz="0.0"
        iyy="0.0000108" iyz="0.0"
        izz="0.0000108"/>
    </inertial>
  </link>
  <joint name="OmniR_roller_18_joint" type="continuous">
    <parent link="OmniR_wheel"/>
    <child  link="OmniR_roller_18"/>
    <origin xyz="0 0.0526 -0.0382" rpy="0 0 0"/>
    <!-- axis = (0, –sin324°, cos324°) = (0, 0.588, 0.809) -->
    <axis xyz="0 0.588 0.809"/>
  </joint>


  <!--==============================================================-->
  <!-- ===== 3) SMALL STABILIZERS (radius = 0.015) at α = 18°,54°,…,342° ===== -->
  <!-- R_small_center = 0.080 m.  Outer = 0.080 + 0.015 = 0.095.        -->
  <!--==============================================================-->

  <!-- Small roller 1 (α =  18°: y ≈ 0.080·cos18° = 0.0761,  z ≈ 0.080·sin18° = 0.0247) -->
  <link name="OmniR_roller_1">
    <collision>
      <origin xyz="0 0 0" rpy="0 0 0"/>
      <geometry>
        <sphere radius="0.015"/>
      </geometry>
    </collision>
    <inertial>
      <!-- Example mass/inertia for a small sphere of radius 0.015. -->
      <mass value="0.5"/>
      <inertia
        ixx="0.00000018" ixy="0.0" ixz="0.0"
        iyy="0.00000018" iyz="0.0"
        izz="0.00000018"/>
    </inertial>
  </link>
  <joint name="OmniR_roller_1_joint" type="continuous">
    <parent link="OmniR_wheel"/>
    <child  link="OmniR_roller_1"/>
    <origin xyz="0 0.0761 0.0247" rpy="0 0 0"/>
    <!-- axis = (0, –sin18°, cos18°) = (0, –0.309, 0.951) -->
    <axis xyz="0 -0.309 0.951"/>
  </joint>

  <!-- Small roller 3 (α =  54°: y ≈ 0.080·cos54° = 0.0470,  z ≈ 0.080·sin54° = 0.0647) -->
  <link name="OmniR_roller_3">
    <collision>
      <origin xyz="0 0 0" rpy="0 0 0"/>
      <geometry>
        <sphere radius="0.015"/>
      </geometry>
    </collision>
    <inertial>
      <mass value="0.5"/>
      <inertia
        ixx="0.00000018" ixy="0.0" ixz="0.0"
        iyy="0.00000018" iyz="0.0"
        izz="0.00000018"/>
    </inertial>
  </link>
  <joint name="OmniR_roller_3_joint" type="continuous">
    <parent link="OmniR_wheel"/>
    <child  link="OmniR_roller_3"/>
    <origin xyz="0 0.0470 0.0647" rpy="0 0 0"/>
    <!-- axis = (0, –sin54°, cos54°) = (0, –0.809, 0.588) -->
    <axis xyz="0 -0.809 0.588"/>
  </joint>

  <!-- Small roller 5 (α =  90°: y = 0.080·cos90° = 0.000,  z = 0.080·sin90° = 0.080) -->
  <link name="OmniR_roller_5">
    <collision>
      <origin xyz="0 0 0" rpy="0 0 0"/>
      <geometry>
        <sphere radius="0.015"/>
      </geometry>
    </collision>
    <inertial>
      <mass value="0.5"/>
      <inertia
        ixx="0.00000018" ixy="0.0" ixz="0.0"
        iyy="0.00000018" iyz="0.0"
        izz="0.00000018"/>
    </inertial>
  </link>
  <joint name="OmniR_roller_5_joint" type="continuous">
    <parent link="OmniR_wheel"/>
    <child  link="OmniR_roller_5"/>
    <origin xyz="0 0.000 0.080" rpy="0 0 0"/>
    <!-- axis = (0, –sin90°, cos90°) = (0, –1, 0) -->
    <axis xyz="0 -1 0"/>
  </joint>

  <!-- Small roller 7 (α = 126°: y ≈ –0.0470,  z ≈ 0.0647) -->
  <link name="OmniR_roller_7">
    <collision>
      <origin xyz="0 0 0" rpy="0 0 0"/>
      <geometry>
        <sphere radius="0.015"/>
      </geometry>
    </collision>
    <inertial>
      <mass value="0.5"/>
      <inertia
        ixx="0.00000018" ixy="0.0" ixz="0.0"
        iyy="0.00000018" iyz="0.0"
        izz="0.00000018"/>
    </inertial>
  </link>
  <joint name="OmniR_roller_7_joint" type="continuous">
    <parent link="OmniR_wheel"/>
    <child  link="OmniR_roller_7"/>
    <origin xyz="0 -0.0470 0.0647" rpy="0 0 0"/>
    <!-- axis = (0, –sin126°, cos126°) = (0, –0.809, –0.588) -->
    <axis xyz="0 -0.809 -0.588"/>
  </joint>

  <!-- Small roller 9 (α = 162°: y ≈ –0.0761,  z ≈ 0.0247) -->
  <link name="OmniR_roller_9">
    <collision>
      <origin xyz="0 0 0" rpy="0 0 0"/>
      <geometry>
        <sphere radius="0.015"/>
      </geometry>
    </collision>
    <inertial>
      <mass value="0.5"/>
      <inertia
        ixx="0.00000018" ixy="0.0" ixz="0.0"
        iyy="0.00000018" iyz="0.0"
        izz="0.00000018"/>
    </inertial>
  </link>
  <joint name="OmniR_roller_9_joint" type="continuous">
    <parent link="OmniR_wheel"/>
    <child  link="OmniR_roller_9"/>
    <origin xyz="0 -0.0761 0.0247" rpy="0 0 0"/>
    <!-- axis = (0, –sin162°, cos162°) = (0, –0.309, –0.951) -->
    <axis xyz="0 -0.309 -0.951"/>
  </joint>

  <!-- Small roller 11 (α = 198°: y ≈ –0.0761,  z ≈ –0.0247) -->
  <link name="OmniR_roller_11">
    <collision>
      <origin xyz="0 0 0" rpy="0 0 0"/>
      <geometry>
        <sphere radius="0.015"/>
      </geometry>
    </collision>
    <inertial>
      <mass value="0.5"/>
      <inertia
        ixx="0.00000018" ixy="0.0" ixz="0.0"
        iyy="0.00000018" iyz="0.0"
        izz="0.00000018"/>
    </inertial>
  </link>
  <joint name="OmniR_roller_11_joint" type="continuous">
    <parent link="OmniR_wheel"/>
    <child  link="OmniR_roller_11"/>
    <origin xyz="0 -0.0761 -0.0247" rpy="0 0 0"/>
    <!-- axis = (0, –sin198°, cos198°) = (0, 0.309, –0.951) -->
    <axis xyz="0 0.309 -0.951"/>
  </joint>

  <!-- Small roller 13 (α = 234°: y ≈ –0.0470,  z ≈ –0.0647) -->
  <link name="OmniR_roller_13">
    <collision>
      <origin xyz="0 0 0" rpy="0 0 0"/>
      <geometry>
        <sphere radius="0.015"/>
      </geometry>
    </collision>
    <inertial>
      <mass value="0.5"/>
      <inertia
        ixx="0.00000018" ixy="0.0" ixz="0.0"
        iyy="0.00000018" iyz="0.0"
        izz="0.00000018"/>
    </inertial>
  </link>
  <joint name="OmniR_roller_13_joint" type="continuous">
    <parent link="OmniR_wheel"/>
    <child  link="OmniR_roller_13"/>
    <origin xyz="0 -0.0470 -0.0647" rpy="0 0 0"/>
    <!-- axis = (0, –sin234°, cos234°) = (0, 0.809, –0.588) -->
    <axis xyz="0 0.809 -0.588"/>
  </joint>

  <!-- Small roller 15 (α = 270°: y = 0.080·cos270° = 0.000,  z = 0.080·sin270° = –0.080) -->
  <link name="OmniR_roller_15">
    <collision>
      <origin xyz="0 0 0" rpy="0 0 0"/>
      <geometry>
        <sphere radius="0.015"/>
      </geometry>
    </collision>
    <inertial>
      <mass value="0.5"/>
      <inertia
        ixx="0.00000018" ixy="0.0" ixz="0.0"
        iyy="0.00000018" iyz="0.0"
        izz="0.00000018"/>
    </inertial>
  </link>
  <joint name="OmniR_roller_15_joint" type="continuous">
    <parent link="OmniR_wheel"/>
    <child  link="OmniR_roller_15"/>
    <origin xyz="0 0.000 -0.080" rpy="0 0 0"/>
    <!-- axis = (0, –sin270°, cos270°) = (0, 1, 0) -->
    <axis xyz="0 1 0"/>
  </joint>

  <!-- Small roller 17 (α = 306°: y ≈ 0.0470,  z ≈ –0.0647) -->
  <link name="OmniR_roller_17">
    <collision>
      <origin xyz="0 0 0" rpy="0 0 0"/>
      <geometry>
        <sphere radius="0.015"/>
      </geometry>
    </collision>
    <inertial>
      <mass value="0.5"/>
      <inertia
        ixx="0.00000018" ixy="0.0" ixz="0.0"
        iyy="0.00000018" iyz="0.0"
        izz="0.00000018"/>
    </inertial>
  </link>
  <joint name="OmniR_roller_17_joint" type="continuous">
    <parent link="OmniR_wheel"/>
    <child  link="OmniR_roller_17"/>
    <origin xyz="0 0.0470 -0.0647" rpy="0 0 0"/>
    <!-- axis = (0, –sin306°, cos306°) = (0, 0.809, 0.588) -->
    <axis xyz="0 0.809 0.588"/>
  </joint>

  <!-- Small roller 19 (α = 342°: y ≈ 0.0761,  z ≈ –0.0247) -->
  <link name="OmniR_roller_19">
    <collision>
      <origin xyz="0 0 0" rpy="0 0 0"/>
      <geometry>
        <sphere radius="0.015"/>
      </geometry>
    </collision>
    <inertial>
      <mass value="0.5"/>
      <inertia
        ixx="0.00000018" ixy="0.0" ixz="0.0"
        iyy="0.00000018" iyz="0.0"
        izz="0.00000018"/>
    </inertial>
  </link>
  <joint name="OmniR_roller_19_joint" type="continuous">
    <parent link="OmniR_wheel"/>
    <child  link="OmniR_roller_19"/>
    <origin xyz="0 0.0761 -0.0247" rpy="0 0 0"/>
    <!-- axis = (0, –sin342°, cos342°) = (0, 0.309, 0.951) -->
    <axis xyz="0 0.309 0.951"/>
  </joint>




  <joint name="OmniFL" type="continuous">
    <parent link="base_link"/>
    <child link="OmniFL_wheel"/>
    <origin xyz="0.105 0.18186525 0.1" rpy="0 0 -2.0944"/>
  </joint>

  <link name="OmniFL_wheel">

  <inertial>
  		<!-- Inertial frame at link origin -->
		<origin xyz="0 0 0" rpy="0 0 0"/>
		<!-- Mass of the base -->
  		<mass value="0.5"/>
      <inertia ixx="0.001" ixy="0." ixz="0." iyy="0.001" iyz="0." izz="0.001"/>
  		<!-- Moments of inertia about the link frame axes -->
	</inertial>
    <visual>
      <origin xyz="0 0 0" rpy="0 0 0"/>
      <geometry>
        <mesh filename="/root/IsaacLab/anubis/meshes/ow206.stl"/>
      </geometry>
      <material name="">
        <color rgba="0.5 0.5 0.5 1"/>
      </material>    
    </visual>
<!-- Inner cylinder -->
    <collision>
      <origin xyz="0 0 0" rpy="0 1.5708 0"/>
      <geometry>
        <cylinder length="0.05" radius="0.08"/>
      </geometry>
    </collision>
    <!-- Outer cylinder -->
    <collision>
      <origin xyz="0 0 0" rpy="0 1.5708 0"/>
      <geometry>
        <cylinder length="0.05" radius="0.029"/>
      </geometry>
    </collision>
    <!-- Ten spheres as rollers -->
    <!-- Angle step = 36 degrees -->
  </link>

  <!--===============================================================-->
  <!-- ===== 2) BIG ROLLERS (radius = 0.03 m) at α = 0°,36°,…,324° ===== -->
  <!-- R_big_center = 0.065 m.  Outer = 0.065 + 0.03 = 0.095.        -->
  <!--===============================================================-->

  <!-- Big roller 0 (α = 0°:  y=0.065, z=0.000) -->
  <link name="OmniFL_roller_0">
    <collision>
      <origin xyz="0 0 0" rpy="0 0 0"/>
      <geometry>
        <sphere radius="0.03"/>
      </geometry>
    </collision>
    <inertial>
      <!-- Example mass/inertia for a uniform sphere of radius 0.03 m. -->
      <mass value="0.5"/>
      <inertia
        ixx="0.0000108" ixy="0.0" ixz="0.0"
        iyy="0.0000108" iyz="0.0"
        izz="0.0000108"/>
    </inertial>
  </link>
  <joint name="OmniFL_roller_0_joint" type="continuous">
    <parent link="OmniFL_wheel"/>
    <child  link="OmniFL_roller_0"/>
    <!-- α =  0° → y = 0.065, z = 0.000 -->
    <origin xyz="0 0.065 0.000" rpy="0 0 0"/>
    <!-- axis = (0, –sin0°, cos0°) = (0, 0, 1) -->
    <axis xyz="0 0 1"/>
  </joint>

  <!-- Big roller 2 (α = 36°:  y = 0.065·cos36° ≈ 0.0526,  z = 0.065·sin36° ≈ 0.0382) -->
  <link name="OmniFL_roller_2">
    <collision>
      <origin xyz="0 0 0" rpy="0 0 0"/>
      <geometry>
        <sphere radius="0.03"/>
      </geometry>
    </collision>
    <inertial>
      <mass value="0.5"/>
      <inertia
        ixx="0.0000108" ixy="0.0" ixz="0.0"
        iyy="0.0000108" iyz="0.0"
        izz="0.0000108"/>
    </inertial>
  </link>
  <joint name="OmniFL_roller_2_joint" type="continuous">
    <parent link="OmniFL_wheel"/>
    <child  link="OmniFL_roller_2"/>
    <origin xyz="0 0.0526 0.0382" rpy="0 0 0"/>
    <!-- axis = (0, –sin36°, cos36°) = (0, –0.588, 0.809) -->
    <axis xyz="0 -0.588 0.809"/>
  </joint>

  <!-- Big roller 4 (α = 72°:  y ≈ 0.065·cos72° = 0.0201,  z ≈ 0.065·sin72° = 0.0617) -->
  <link name="OmniFL_roller_4">
    <collision>
      <origin xyz="0 0 0" rpy="0 0 0"/>
      <geometry>
        <sphere radius="0.03"/>
      </geometry>
    </collision>
    <inertial>
      <mass value="0.5"/>
      <inertia
        ixx="0.0000108" ixy="0.0" ixz="0.0"
        iyy="0.0000108" iyz="0.0"
        izz="0.0000108"/>
    </inertial>
  </link>
  <joint name="OmniFL_roller_4_joint" type="continuous">
    <parent link="OmniFL_wheel"/>
    <child  link="OmniFL_roller_4"/>
    <origin xyz="0 0.0201 0.0617" rpy="0 0 0"/>
    <!-- axis = (0, –sin72°, cos72°) = (0, –0.951, 0.309) approximated -->
    <axis xyz="0 -0.951 0.309"/>
  </joint>

  <!-- Big roller 6 (α = 108°:  y = 0.065·cos108° ≈ –0.0201,  z = 0.065·sin108° ≈ 0.0617) -->
  <link name="OmniFL_roller_6">
    <collision>
      <origin xyz="0 0 0" rpy="0 0 0"/>
      <geometry>
        <sphere radius="0.03"/>
      </geometry>
    </collision>
    <inertial>
      <mass value="0.5"/>
      <inertia
        ixx="0.0000108" ixy="0.0" ixz="0.0"
        iyy="0.0000108" iyz="0.0"
        izz="0.0000108"/>
    </inertial>
  </link>
  <joint name="OmniFL_roller_6_joint" type="continuous">
    <parent link="OmniFL_wheel"/>
    <child  link="OmniFL_roller_6"/>
    <origin xyz="0 -0.0201 0.0617" rpy="0 0 0"/>
    <!-- axis = (0, –sin108°, cos108°) = (0, –0.951, –0.309) -->
    <axis xyz="0 -0.951 -0.309"/>
  </joint>

  <!-- Big roller 8 (α = 144°:  y ≈ –0.0526,  z ≈ 0.0382) -->
  <link name="OmniFL_roller_8">
    <collision>
      <origin xyz="0 0 0" rpy="0 0 0"/>
      <geometry>
        <sphere radius="0.03"/>
      </geometry>
    </collision>
    <inertial>
      <mass value="0.5"/>
      <inertia
        ixx="0.0000108" ixy="0.0" ixz="0.0"
        iyy="0.0000108" iyz="0.0"
        izz="0.0000108"/>
    </inertial>
  </link>
  <joint name="OmniFL_roller_8_joint" type="continuous">
    <parent link="OmniFL_wheel"/>
    <child  link="OmniFL_roller_8"/>
    <origin xyz="0 -0.0526 0.0382" rpy="0 0 0"/>
    <!-- axis = (0, –sin144°, cos144°) = (0, –0.588, –0.809) -->
    <axis xyz="0 -0.588 -0.809"/>
  </joint>

  <!-- Big roller 10 (α = 180°:  y = –0.065,  z = 0) -->
  <link name="OmniFL_roller_10">
    <collision>
      <origin xyz="0 0 0" rpy="0 0 0"/>
      <geometry>
        <sphere radius="0.03"/>
      </geometry>
    </collision>
    <inertial>
      <mass value="0.5"/>
      <inertia
        ixx="0.0000108" ixy="0.0" ixz="0.0"
        iyy="0.0000108" iyz="0.0"
        izz="0.0000108"/>
    </inertial>
  </link>
  <joint name="OmniFL_roller_10_joint" type="continuous">
    <parent link="OmniFL_wheel"/>
    <child  link="OmniFL_roller_10"/>
    <origin xyz="0 -0.065 0.000" rpy="0 0 0"/>
    <!-- axis = (0, –sin180°, cos180°) = (0, 0, –1) -->
    <axis xyz="0 0 -1"/>
  </joint>

  <!-- Big roller 12 (α = 216°:  y ≈ –0.0526,  z ≈ –0.0382) -->
  <link name="OmniFL_roller_12">
    <collision>
      <origin xyz="0 0 0" rpy="0 0 0"/>
      <geometry>
        <sphere radius="0.03"/>
      </geometry>
    </collision>
    <inertial>
      <mass value="0.5"/>
      <inertia
        ixx="0.0000108" ixy="0.0" ixz="0.0"
        iyy="0.0000108" iyz="0.0"
        izz="0.0000108"/>
    </inertial>
  </link>
  <joint name="OmniFL_roller_12_joint" type="continuous">
    <parent link="OmniFL_wheel"/>
    <child  link="OmniFL_roller_12"/>
    <origin xyz="0 -0.0526 -0.0382" rpy="0 0 0"/>
    <!-- axis = (0, –sin216°, cos216°) = (0, 0.588, –0.809) -->
    <axis xyz="0 0.588 -0.809"/>
  </joint>

  <!-- Big roller 14 (α = 252°:  y ≈ –0.0201,  z ≈ –0.0617) -->
  <link name="OmniFL_roller_14">
    <collision>
      <origin xyz="0 0 0" rpy="0 0 0"/>
      <geometry>
        <sphere radius="0.03"/>
      </geometry>
    </collision>
    <inertial>
      <mass value="0.5"/>
      <inertia
        ixx="0.0000108" ixy="0.0" ixz="0.0"
        iyy="0.0000108" iyz="0.0"
        izz="0.0000108"/>
    </inertial>
  </link>
  <joint name="OmniFL_roller_14_joint" type="continuous">
    <parent link="OmniFL_wheel"/>
    <child  link="OmniFL_roller_14"/>
    <origin xyz="0 -0.0201 -0.0617" rpy="0 0 0"/>
    <!-- axis = (0, –sin252°, cos252°) = (0, 0.951, –0.309) -->
    <axis xyz="0 0.951 -0.309"/>
  </joint>

  <!-- Big roller 16 (α = 288°:  y ≈ 0.0201,  z ≈ –0.0617) -->
  <link name="OmniFL_roller_16">
    <collision>
      <origin xyz="0 0 0" rpy="0 0 0"/>
      <geometry>
        <sphere radius="0.03"/>
      </geometry>
    </collision>
    <inertial>
      <mass value="0.5"/>
      <inertia
        ixx="0.0000108" ixy="0.0" ixz="0.0"
        iyy="0.0000108" iyz="0.0"
        izz="0.0000108"/>
    </inertial>
  </link>
  <joint name="OmniFL_roller_16_joint" type="continuous">
    <parent link="OmniFL_wheel"/>
    <child  link="OmniFL_roller_16"/>
    <origin xyz="0 0.0201 -0.0617" rpy="0 0 0"/>
    <!-- axis = (0, –sin288°, cos288°) = (0, 0.951, 0.309) -->
    <axis xyz="0 0.951 0.309"/>
  </joint>

  <!-- Big roller 18 (α = 324°:  y ≈ 0.0526,  z ≈ –0.0382) -->
  <link name="OmniFL_roller_18">
    <collision>
      <origin xyz="0 0 0" rpy="0 0 0"/>
      <geometry>
        <sphere radius="0.03"/>
      </geometry>
    </collision>
    <inertial>
      <mass value="0.5"/>
      <inertia
        ixx="0.0000108" ixy="0.0" ixz="0.0"
        iyy="0.0000108" iyz="0.0"
        izz="0.0000108"/>
    </inertial>
  </link>
  <joint name="OmniFL_roller_18_joint" type="continuous">
    <parent link="OmniFL_wheel"/>
    <child  link="OmniFL_roller_18"/>
    <origin xyz="0 0.0526 -0.0382" rpy="0 0 0"/>
    <!-- axis = (0, –sin324°, cos324°) = (0, 0.588, 0.809) -->
    <axis xyz="0 0.588 0.809"/>
  </joint>


  <!--==============================================================-->
  <!-- ===== 3) SMALL STABILIZERS (radius = 0.015) at α = 18°,54°,…,342° ===== -->
  <!-- R_small_center = 0.080 m.  Outer = 0.080 + 0.015 = 0.095.        -->
  <!--==============================================================-->

  <!-- Small roller 1 (α =  18°: y ≈ 0.080·cos18° = 0.0761,  z ≈ 0.080·sin18° = 0.0247) -->
  <link name="OmniFL_roller_1">
    <collision>
      <origin xyz="0 0 0" rpy="0 0 0"/>
      <geometry>
        <sphere radius="0.015"/>
      </geometry>
    </collision>
    <inertial>
      <!-- Example mass/inertia for a small sphere of radius 0.015. -->
      <mass value="0.5"/>
      <inertia
        ixx="0.00000018" ixy="0.0" ixz="0.0"
        iyy="0.00000018" iyz="0.0"
        izz="0.00000018"/>
    </inertial>
  </link>
  <joint name="OmniFL_roller_1_joint" type="continuous">
    <parent link="OmniFL_wheel"/>
    <child  link="OmniFL_roller_1"/>
    <origin xyz="0 0.0761 0.0247" rpy="0 0 0"/>
    <!-- axis = (0, –sin18°, cos18°) = (0, –0.309, 0.951) -->
    <axis xyz="0 -0.309 0.951"/>
  </joint>

  <!-- Small roller 3 (α =  54°: y ≈ 0.080·cos54° = 0.0470,  z ≈ 0.080·sin54° = 0.0647) -->
  <link name="OmniFL_roller_3">
    <collision>
      <origin xyz="0 0 0" rpy="0 0 0"/>
      <geometry>
        <sphere radius="0.015"/>
      </geometry>
    </collision>
    <inertial>
      <mass value="0.5"/>
      <inertia
        ixx="0.00000018" ixy="0.0" ixz="0.0"
        iyy="0.00000018" iyz="0.0"
        izz="0.00000018"/>
    </inertial>
  </link>
  <joint name="OmniFL_roller_3_joint" type="continuous">
    <parent link="OmniFL_wheel"/>
    <child  link="OmniFL_roller_3"/>
    <origin xyz="0 0.0470 0.0647" rpy="0 0 0"/>
    <!-- axis = (0, –sin54°, cos54°) = (0, –0.809, 0.588) -->
    <axis xyz="0 -0.809 0.588"/>
  </joint>

  <!-- Small roller 5 (α =  90°: y = 0.080·cos90° = 0.000,  z = 0.080·sin90° = 0.080) -->
  <link name="OmniFL_roller_5">
    <collision>
      <origin xyz="0 0 0" rpy="0 0 0"/>
      <geometry>
        <sphere radius="0.015"/>
      </geometry>
    </collision>
    <inertial>
      <mass value="0.5"/>
      <inertia
        ixx="0.00000018" ixy="0.0" ixz="0.0"
        iyy="0.00000018" iyz="0.0"
        izz="0.00000018"/>
    </inertial>
  </link>
  <joint name="OmniFL_roller_5_joint" type="continuous">
    <parent link="OmniFL_wheel"/>
    <child  link="OmniFL_roller_5"/>
    <origin xyz="0 0.000 0.080" rpy="0 0 0"/>
    <!-- axis = (0, –sin90°, cos90°) = (0, –1, 0) -->
    <axis xyz="0 -1 0"/>
  </joint>

  <!-- Small roller 7 (α = 126°: y ≈ –0.0470,  z ≈ 0.0647) -->
  <link name="OmniFL_roller_7">
    <collision>
      <origin xyz="0 0 0" rpy="0 0 0"/>
      <geometry>
        <sphere radius="0.015"/>
      </geometry>
    </collision>
    <inertial>
      <mass value="0.5"/>
      <inertia
        ixx="0.00000018" ixy="0.0" ixz="0.0"
        iyy="0.00000018" iyz="0.0"
        izz="0.00000018"/>
    </inertial>
  </link>
  <joint name="OmniFL_roller_7_joint" type="continuous">
    <parent link="OmniFL_wheel"/>
    <child  link="OmniFL_roller_7"/>
    <origin xyz="0 -0.0470 0.0647" rpy="0 0 0"/>
    <!-- axis = (0, –sin126°, cos126°) = (0, –0.809, –0.588) -->
    <axis xyz="0 -0.809 -0.588"/>
  </joint>

  <!-- Small roller 9 (α = 162°: y ≈ –0.0761,  z ≈ 0.0247) -->
  <link name="OmniFL_roller_9">
    <collision>
      <origin xyz="0 0 0" rpy="0 0 0"/>
      <geometry>
        <sphere radius="0.015"/>
      </geometry>
    </collision>
    <inertial>
      <mass value="0.5"/>
      <inertia
        ixx="0.00000018" ixy="0.0" ixz="0.0"
        iyy="0.00000018" iyz="0.0"
        izz="0.00000018"/>
    </inertial>
  </link>
  <joint name="OmniFL_roller_9_joint" type="continuous">
    <parent link="OmniFL_wheel"/>
    <child  link="OmniFL_roller_9"/>
    <origin xyz="0 -0.0761 0.0247" rpy="0 0 0"/>
    <!-- axis = (0, –sin162°, cos162°) = (0, –0.309, –0.951) -->
    <axis xyz="0 -0.309 -0.951"/>
  </joint>

  <!-- Small roller 11 (α = 198°: y ≈ –0.0761,  z ≈ –0.0247) -->
  <link name="OmniFL_roller_11">
    <collision>
      <origin xyz="0 0 0" rpy="0 0 0"/>
      <geometry>
        <sphere radius="0.015"/>
      </geometry>
    </collision>
    <inertial>
      <mass value="0.5"/>
      <inertia
        ixx="0.00000018" ixy="0.0" ixz="0.0"
        iyy="0.00000018" iyz="0.0"
        izz="0.00000018"/>
    </inertial>
  </link>
  <joint name="OmniFL_roller_11_joint" type="continuous">
    <parent link="OmniFL_wheel"/>
    <child  link="OmniFL_roller_11"/>
    <origin xyz="0 -0.0761 -0.0247" rpy="0 0 0"/>
    <!-- axis = (0, –sin198°, cos198°) = (0, 0.309, –0.951) -->
    <axis xyz="0 0.309 -0.951"/>
  </joint>

  <!-- Small roller 13 (α = 234°: y ≈ –0.0470,  z ≈ –0.0647) -->
  <link name="OmniFL_roller_13">
    <collision>
      <origin xyz="0 0 0" rpy="0 0 0"/>
      <geometry>
        <sphere radius="0.015"/>
      </geometry>
    </collision>
    <inertial>
      <mass value="0.5"/>
      <inertia
        ixx="0.00000018" ixy="0.0" ixz="0.0"
        iyy="0.00000018" iyz="0.0"
        izz="0.00000018"/>
    </inertial>
  </link>
  <joint name="OmniFL_roller_13_joint" type="continuous">
    <parent link="OmniFL_wheel"/>
    <child  link="OmniFL_roller_13"/>
    <origin xyz="0 -0.0470 -0.0647" rpy="0 0 0"/>
    <!-- axis = (0, –sin234°, cos234°) = (0, 0.809, –0.588) -->
    <axis xyz="0 0.809 -0.588"/>
  </joint>

  <!-- Small roller 15 (α = 270°: y = 0.080·cos270° = 0.000,  z = 0.080·sin270° = –0.080) -->
  <link name="OmniFL_roller_15">
    <collision>
      <origin xyz="0 0 0" rpy="0 0 0"/>
      <geometry>
        <sphere radius="0.015"/>
      </geometry>
    </collision>
    <inertial>
      <mass value="0.5"/>
      <inertia
        ixx="0.00000018" ixy="0.0" ixz="0.0"
        iyy="0.00000018" iyz="0.0"
        izz="0.00000018"/>
    </inertial>
  </link>
  <joint name="OmniFL_roller_15_joint" type="continuous">
    <parent link="OmniFL_wheel"/>
    <child  link="OmniFL_roller_15"/>
    <origin xyz="0 0.000 -0.080" rpy="0 0 0"/>
    <!-- axis = (0, –sin270°, cos270°) = (0, 1, 0) -->
    <axis xyz="0 1 0"/>
  </joint>

  <!-- Small roller 17 (α = 306°: y ≈ 0.0470,  z ≈ –0.0647) -->
  <link name="OmniFL_roller_17">
    <collision>
      <origin xyz="0 0 0" rpy="0 0 0"/>
      <geometry>
        <sphere radius="0.015"/>
      </geometry>
    </collision>
    <inertial>
      <mass value="0.5"/>
      <inertia
        ixx="0.00000018" ixy="0.0" ixz="0.0"
        iyy="0.00000018" iyz="0.0"
        izz="0.00000018"/>
    </inertial>
  </link>
  <joint name="OmniFL_roller_17_joint" type="continuous">
    <parent link="OmniFL_wheel"/>
    <child  link="OmniFL_roller_17"/>
    <origin xyz="0 0.0470 -0.0647" rpy="0 0 0"/>
    <!-- axis = (0, –sin306°, cos306°) = (0, 0.809, 0.588) -->
    <axis xyz="0 0.809 0.588"/>
  </joint>

  <!-- Small roller 19 (α = 342°: y ≈ 0.0761,  z ≈ –0.0247) -->
  <link name="OmniFL_roller_19">
    <collision>
      <origin xyz="0 0 0" rpy="0 0 0"/>
      <geometry>
        <sphere radius="0.015"/>
      </geometry>
    </collision>
    <inertial>
      <mass value="0.5"/>
      <inertia
        ixx="0.00000018" ixy="0.0" ixz="0.0"
        iyy="0.00000018" iyz="0.0"
        izz="0.00000018"/>
    </inertial>
  </link>
  <joint name="OmniFL_roller_19_joint" type="continuous">
    <parent link="OmniFL_wheel"/>
    <child  link="OmniFL_roller_19"/>
    <origin xyz="0 0.0761 -0.0247" rpy="0 0 0"/>
    <!-- axis = (0, –sin342°, cos342°) = (0, 0.309, 0.951) -->
    <axis xyz="0 0.309 0.951"/>
  </joint>



  <joint name="OmniFR" type="continuous">
    <parent link="base_link"/>
    <child link="OmniFR_wheel"/>
    <origin xyz="0.105 -0.18186525 0.1" rpy="0 0 2.0944"/>
  </joint>

  <link name="OmniFR_wheel">
    <inertial>
  		<!-- Inertial frame at link origin -->
		<origin xyz="0 0 0" rpy="0 0 0"/>
		<!-- Mass of the base -->
  		<mass value="0.5"/>
      <inertia ixx="0.001" ixy="0." ixz="0." iyy="0.001" iyz="0." izz="0.001"/>
  		<!-- Moments of inertia about the link frame axes -->
	</inertial>
    <visual>
      <origin xyz="0 0 0" rpy="0 0 0"/>
      <geometry>
        <mesh filename="/root/IsaacLab/anubis/meshes/ow206.stl"/>
      </geometry>
      <material name="">
        <color rgba="0.5 0.5 0.5 1"/>
      </material>    
    </visual>
<!-- Inner cylinder -->
    <collision>
      <origin xyz="0 0 0" rpy="0 1.5708 0"/>
      <geometry>
        <cylinder length="0.05" radius="0.08"/>
      </geometry>
    </collision>
    <!-- Outer cylinder -->
    <collision>
      <origin xyz="0 0 0" rpy="0 1.5708 0"/>
      <geometry>
        <cylinder length="0.05" radius="0.029"/>
      </geometry>
    </collision>
  </link>
<!-- Alternating rollers -->
  <!--===============================================================-->
  <!-- ===== 2) BIG ROLLERS (radius = 0.03 m) at α = 0°,36°,…,324° ===== -->
  <!-- R_big_center = 0.065 m.  Outer = 0.065 + 0.03 = 0.095.        -->
  <!--===============================================================-->

  <!-- Big roller 0 (α = 0°:  y=0.065, z=0.000) -->
  <link name="OmniFR_roller_0">
    <collision>
      <origin xyz="0 0 0" rpy="0 0 0"/>
      <geometry>
        <sphere radius="0.03"/>
      </geometry>
    </collision>
    <inertial>
      <!-- Example mass/inertia for a uniform sphere of radius 0.03 m. -->
      <mass value="0.5"/>
      <inertia
        ixx="0.0000108" ixy="0.0" ixz="0.0"
        iyy="0.0000108" iyz="0.0"
        izz="0.0000108"/>
    </inertial>
  </link>
  <joint name="OmniFR_roller_0_joint" type="continuous">
    <parent link="OmniFR_wheel"/>
    <child  link="OmniFR_roller_0"/>
    <!-- α =  0° → y = 0.065, z = 0.000 -->
    <origin xyz="0 0.065 0.000" rpy="0 0 0"/>
    <!-- axis = (0, –sin0°, cos0°) = (0, 0, 1) -->
    <axis xyz="0 0 1"/>
  </joint>

  <!-- Big roller 2 (α = 36°:  y = 0.065·cos36° ≈ 0.0526,  z = 0.065·sin36° ≈ 0.0382) -->
  <link name="OmniFR_roller_2">
    <collision>
      <origin xyz="0 0 0" rpy="0 0 0"/>
      <geometry>
        <sphere radius="0.03"/>
      </geometry>
    </collision>
    <inertial>
      <mass value="0.5"/>
      <inertia
        ixx="0.0000108" ixy="0.0" ixz="0.0"
        iyy="0.0000108" iyz="0.0"
        izz="0.0000108"/>
    </inertial>
  </link>
  <joint name="OmniFR_roller_2_joint" type="continuous">
    <parent link="OmniFR_wheel"/>
    <child  link="OmniFR_roller_2"/>
    <origin xyz="0 0.0526 0.0382" rpy="0 0 0"/>
    <!-- axis = (0, –sin36°, cos36°) = (0, –0.588, 0.809) -->
    <axis xyz="0 -0.588 0.809"/>
  </joint>

  <!-- Big roller 4 (α = 72°:  y ≈ 0.065·cos72° = 0.0201,  z ≈ 0.065·sin72° = 0.0617) -->
  <link name="OmniFR_roller_4">
    <collision>
      <origin xyz="0 0 0" rpy="0 0 0"/>
      <geometry>
        <sphere radius="0.03"/>
      </geometry>
    </collision>
    <inertial>
      <mass value="0.5"/>
      <inertia
        ixx="0.0000108" ixy="0.0" ixz="0.0"
        iyy="0.0000108" iyz="0.0"
        izz="0.0000108"/>
    </inertial>
  </link>
  <joint name="OmniFR_roller_4_joint" type="continuous">
    <parent link="OmniFR_wheel"/>
    <child  link="OmniFR_roller_4"/>
    <origin xyz="0 0.0201 0.0617" rpy="0 0 0"/>
    <!-- axis = (0, –sin72°, cos72°) = (0, –0.951, 0.309) approximated -->
    <axis xyz="0 -0.951 0.309"/>
  </joint>

  <!-- Big roller 6 (α = 108°:  y = 0.065·cos108° ≈ –0.0201,  z = 0.065·sin108° ≈ 0.0617) -->
  <link name="OmniFR_roller_6">
    <collision>
      <origin xyz="0 0 0" rpy="0 0 0"/>
      <geometry>
        <sphere radius="0.03"/>
      </geometry>
    </collision>
    <inertial>
      <mass value="0.5"/>
      <inertia
        ixx="0.0000108" ixy="0.0" ixz="0.0"
        iyy="0.0000108" iyz="0.0"
        izz="0.0000108"/>
    </inertial>
  </link>
  <joint name="OmniFR_roller_6_joint" type="continuous">
    <parent link="OmniFR_wheel"/>
    <child  link="OmniFR_roller_6"/>
    <origin xyz="0 -0.0201 0.0617" rpy="0 0 0"/>
    <!-- axis = (0, –sin108°, cos108°) = (0, –0.951, –0.309) -->
    <axis xyz="0 -0.951 -0.309"/>
  </joint>

  <!-- Big roller 8 (α = 144°:  y ≈ –0.0526,  z ≈ 0.0382) -->
  <link name="OmniFR_roller_8">
    <collision>
      <origin xyz="0 0 0" rpy="0 0 0"/>
      <geometry>
        <sphere radius="0.03"/>
      </geometry>
    </collision>
    <inertial>
      <mass value="0.5"/>
      <inertia
        ixx="0.0000108" ixy="0.0" ixz="0.0"
        iyy="0.0000108" iyz="0.0"
        izz="0.0000108"/>
    </inertial>
  </link>
  <joint name="OmniFR_roller_8_joint" type="continuous">
    <parent link="OmniFR_wheel"/>
    <child  link="OmniFR_roller_8"/>
    <origin xyz="0 -0.0526 0.0382" rpy="0 0 0"/>
    <!-- axis = (0, –sin144°, cos144°) = (0, –0.588, –0.809) -->
    <axis xyz="0 -0.588 -0.809"/>
  </joint>

  <!-- Big roller 10 (α = 180°:  y = –0.065,  z = 0) -->
  <link name="OmniFR_roller_10">
    <collision>
      <origin xyz="0 0 0" rpy="0 0 0"/>
      <geometry>
        <sphere radius="0.03"/>
      </geometry>
    </collision>
    <inertial>
      <mass value="0.5"/>
      <inertia
        ixx="0.0000108" ixy="0.0" ixz="0.0"
        iyy="0.0000108" iyz="0.0"
        izz="0.0000108"/>
    </inertial>
  </link>
  <joint name="OmniFR_roller_10_joint" type="continuous">
    <parent link="OmniFR_wheel"/>
    <child  link="OmniFR_roller_10"/>
    <origin xyz="0 -0.065 0.000" rpy="0 0 0"/>
    <!-- axis = (0, –sin180°, cos180°) = (0, 0, –1) -->
    <axis xyz="0 0 -1"/>
  </joint>

  <!-- Big roller 12 (α = 216°:  y ≈ –0.0526,  z ≈ –0.0382) -->
  <link name="OmniFR_roller_12">
    <collision>
      <origin xyz="0 0 0" rpy="0 0 0"/>
      <geometry>
        <sphere radius="0.03"/>
      </geometry>
    </collision>
    <inertial>
      <mass value="0.5"/>
      <inertia
        ixx="0.0000108" ixy="0.0" ixz="0.0"
        iyy="0.0000108" iyz="0.0"
        izz="0.0000108"/>
    </inertial>
  </link>
  <joint name="OmniFR_roller_12_joint" type="continuous">
    <parent link="OmniFR_wheel"/>
    <child  link="OmniFR_roller_12"/>
    <origin xyz="0 -0.0526 -0.0382" rpy="0 0 0"/>
    <!-- axis = (0, –sin216°, cos216°) = (0, 0.588, –0.809) -->
    <axis xyz="0 0.588 -0.809"/>
  </joint>

  <!-- Big roller 14 (α = 252°:  y ≈ –0.0201,  z ≈ –0.0617) -->
  <link name="OmniFR_roller_14">
    <collision>
      <origin xyz="0 0 0" rpy="0 0 0"/>
      <geometry>
        <sphere radius="0.03"/>
      </geometry>
    </collision>
    <inertial>
      <mass value="0.5"/>
      <inertia
        ixx="0.0000108" ixy="0.0" ixz="0.0"
        iyy="0.0000108" iyz="0.0"
        izz="0.0000108"/>
    </inertial>
  </link>
  <joint name="OmniFR_roller_14_joint" type="continuous">
    <parent link="OmniFR_wheel"/>
    <child  link="OmniFR_roller_14"/>
    <origin xyz="0 -0.0201 -0.0617" rpy="0 0 0"/>
    <!-- axis = (0, –sin252°, cos252°) = (0, 0.951, –0.309) -->
    <axis xyz="0 0.951 -0.309"/>
  </joint>

  <!-- Big roller 16 (α = 288°:  y ≈ 0.0201,  z ≈ –0.0617) -->
  <link name="OmniFR_roller_16">
    <collision>
      <origin xyz="0 0 0" rpy="0 0 0"/>
      <geometry>
        <sphere radius="0.03"/>
      </geometry>
    </collision>
    <inertial>
      <mass value="0.5"/>
      <inertia
        ixx="0.0000108" ixy="0.0" ixz="0.0"
        iyy="0.0000108" iyz="0.0"
        izz="0.0000108"/>
    </inertial>
  </link>
  <joint name="OmniFR_roller_16_joint" type="continuous">
    <parent link="OmniFR_wheel"/>
    <child  link="OmniFR_roller_16"/>
    <origin xyz="0 0.0201 -0.0617" rpy="0 0 0"/>
    <!-- axis = (0, –sin288°, cos288°) = (0, 0.951, 0.309) -->
    <axis xyz="0 0.951 0.309"/>
  </joint>

  <!-- Big roller 18 (α = 324°:  y ≈ 0.0526,  z ≈ –0.0382) -->
  <link name="OmniFR_roller_18">
    <collision>
      <origin xyz="0 0 0" rpy="0 0 0"/>
      <geometry>
        <sphere radius="0.03"/>
      </geometry>
    </collision>
    <inertial>
      <mass value="0.5"/>
      <inertia
        ixx="0.0000108" ixy="0.0" ixz="0.0"
        iyy="0.0000108" iyz="0.0"
        izz="0.0000108"/>
    </inertial>
  </link>
  <joint name="OmniFR_roller_18_joint" type="continuous">
    <parent link="OmniFR_wheel"/>
    <child  link="OmniFR_roller_18"/>
    <origin xyz="0 0.0526 -0.0382" rpy="0 0 0"/>
    <!-- axis = (0, –sin324°, cos324°) = (0, 0.588, 0.809) -->
    <axis xyz="0 0.588 0.809"/>
  </joint>


  <!--==============================================================-->
  <!-- ===== 3) SMALL STABILIZERS (radius = 0.015) at α = 18°,54°,…,342° ===== -->
  <!-- R_small_center = 0.080 m.  Outer = 0.080 + 0.015 = 0.095.        -->
  <!--==============================================================-->

  <!-- Small roller 1 (α =  18°: y ≈ 0.080·cos18° = 0.0761,  z ≈ 0.080·sin18° = 0.0247) -->
  <link name="OmniFR_roller_1">
    <collision>
      <origin xyz="0 0 0" rpy="0 0 0"/>
      <geometry>
        <sphere radius="0.015"/>
      </geometry>
    </collision>
    <inertial>
      <!-- Example mass/inertia for a small sphere of radius 0.015. -->
      <mass value="0.5"/>
      <inertia
        ixx="0.00000018" ixy="0.0" ixz="0.0"
        iyy="0.00000018" iyz="0.0"
        izz="0.00000018"/>
    </inertial>
  </link>
  <joint name="OmniFR_roller_1_joint" type="continuous">
    <parent link="OmniFR_wheel"/>
    <child  link="OmniFR_roller_1"/>
    <origin xyz="0 0.0761 0.0247" rpy="0 0 0"/>
    <!-- axis = (0, –sin18°, cos18°) = (0, –0.309, 0.951) -->
    <axis xyz="0 -0.309 0.951"/>
  </joint>

  <!-- Small roller 3 (α =  54°: y ≈ 0.080·cos54° = 0.0470,  z ≈ 0.080·sin54° = 0.0647) -->
  <link name="OmniFR_roller_3">
    <collision>
      <origin xyz="0 0 0" rpy="0 0 0"/>
      <geometry>
        <sphere radius="0.015"/>
      </geometry>
    </collision>
    <inertial>
      <mass value="0.5"/>
      <inertia
        ixx="0.00000018" ixy="0.0" ixz="0.0"
        iyy="0.00000018" iyz="0.0"
        izz="0.00000018"/>
    </inertial>
  </link>
  <joint name="OmniFR_roller_3_joint" type="continuous">
    <parent link="OmniFR_wheel"/>
    <child  link="OmniFR_roller_3"/>
    <origin xyz="0 0.0470 0.0647" rpy="0 0 0"/>
    <!-- axis = (0, –sin54°, cos54°) = (0, –0.809, 0.588) -->
    <axis xyz="0 -0.809 0.588"/>
  </joint>

  <!-- Small roller 5 (α =  90°: y = 0.080·cos90° = 0.000,  z = 0.080·sin90° = 0.080) -->
  <link name="OmniFR_roller_5">
    <collision>
      <origin xyz="0 0 0" rpy="0 0 0"/>
      <geometry>
        <sphere radius="0.015"/>
      </geometry>
    </collision>
    <inertial>
      <mass value="0.5"/>
      <inertia
        ixx="0.00000018" ixy="0.0" ixz="0.0"
        iyy="0.00000018" iyz="0.0"
        izz="0.00000018"/>
    </inertial>
  </link>
  <joint name="OmniFR_roller_5_joint" type="continuous">
    <parent link="OmniFR_wheel"/>
    <child  link="OmniFR_roller_5"/>
    <origin xyz="0 0.000 0.080" rpy="0 0 0"/>
    <!-- axis = (0, –sin90°, cos90°) = (0, –1, 0) -->
    <axis xyz="0 -1 0"/>
  </joint>

  <!-- Small roller 7 (α = 126°: y ≈ –0.0470,  z ≈ 0.0647) -->
  <link name="OmniFR_roller_7">
    <collision>
      <origin xyz="0 0 0" rpy="0 0 0"/>
      <geometry>
        <sphere radius="0.015"/>
      </geometry>
    </collision>
    <inertial>
      <mass value="0.5"/>
      <inertia
        ixx="0.00000018" ixy="0.0" ixz="0.0"
        iyy="0.00000018" iyz="0.0"
        izz="0.00000018"/>
    </inertial>
  </link>
  <joint name="OmniFR_roller_7_joint" type="continuous">
    <parent link="OmniFR_wheel"/>
    <child  link="OmniFR_roller_7"/>
    <origin xyz="0 -0.0470 0.0647" rpy="0 0 0"/>
    <!-- axis = (0, –sin126°, cos126°) = (0, –0.809, –0.588) -->
    <axis xyz="0 -0.809 -0.588"/>
  </joint>

  <!-- Small roller 9 (α = 162°: y ≈ –0.0761,  z ≈ 0.0247) -->
  <link name="OmniFR_roller_9">
    <collision>
      <origin xyz="0 0 0" rpy="0 0 0"/>
      <geometry>
        <sphere radius="0.015"/>
      </geometry>
    </collision>
    <inertial>
      <mass value="0.5"/>
      <inertia
        ixx="0.00000018" ixy="0.0" ixz="0.0"
        iyy="0.00000018" iyz="0.0"
        izz="0.00000018"/>
    </inertial>
  </link>
  <joint name="OmniFR_roller_9_joint" type="continuous">
    <parent link="OmniFR_wheel"/>
    <child  link="OmniFR_roller_9"/>
    <origin xyz="0 -0.0761 0.0247" rpy="0 0 0"/>
    <!-- axis = (0, –sin162°, cos162°) = (0, –0.309, –0.951) -->
    <axis xyz="0 -0.309 -0.951"/>
  </joint>

  <!-- Small roller 11 (α = 198°: y ≈ –0.0761,  z ≈ –0.0247) -->
  <link name="OmniFR_roller_11">
    <collision>
      <origin xyz="0 0 0" rpy="0 0 0"/>
      <geometry>
        <sphere radius="0.015"/>
      </geometry>
    </collision>
    <inertial>
      <mass value="0.5"/>
      <inertia
        ixx="0.00000018" ixy="0.0" ixz="0.0"
        iyy="0.00000018" iyz="0.0"
        izz="0.00000018"/>
    </inertial>
  </link>
  <joint name="OmniFR_roller_11_joint" type="continuous">
    <parent link="OmniFR_wheel"/>
    <child  link="OmniFR_roller_11"/>
    <origin xyz="0 -0.0761 -0.0247" rpy="0 0 0"/>
    <!-- axis = (0, –sin198°, cos198°) = (0, 0.309, –0.951) -->
    <axis xyz="0 0.309 -0.951"/>
  </joint>

  <!-- Small roller 13 (α = 234°: y ≈ –0.0470,  z ≈ –0.0647) -->
  <link name="OmniFR_roller_13">
    <collision>
      <origin xyz="0 0 0" rpy="0 0 0"/>
      <geometry>
        <sphere radius="0.015"/>
      </geometry>
    </collision>
    <inertial>
      <mass value="0.5"/>
      <inertia
        ixx="0.00000018" ixy="0.0" ixz="0.0"
        iyy="0.00000018" iyz="0.0"
        izz="0.00000018"/>
    </inertial>
  </link>
  <joint name="OmniFR_roller_13_joint" type="continuous">
    <parent link="OmniFR_wheel"/>
    <child  link="OmniFR_roller_13"/>
    <origin xyz="0 -0.0470 -0.0647" rpy="0 0 0"/>
    <!-- axis = (0, –sin234°, cos234°) = (0, 0.809, –0.588) -->
    <axis xyz="0 0.809 -0.588"/>
  </joint>

  <!-- Small roller 15 (α = 270°: y = 0.080·cos270° = 0.000,  z = 0.080·sin270° = –0.080) -->
  <link name="OmniFR_roller_15">
    <collision>
      <origin xyz="0 0 0" rpy="0 0 0"/>
      <geometry>
        <sphere radius="0.015"/>
      </geometry>
    </collision>
    <inertial>
      <mass value="0.5"/>
      <inertia
        ixx="0.00000018" ixy="0.0" ixz="0.0"
        iyy="0.00000018" iyz="0.0"
        izz="0.00000018"/>
    </inertial>
  </link>
  <joint name="OmniFR_roller_15_joint" type="continuous">
    <parent link="OmniFR_wheel"/>
    <child  link="OmniFR_roller_15"/>
    <origin xyz="0 0.000 -0.080" rpy="0 0 0"/>
    <!-- axis = (0, –sin270°, cos270°) = (0, 1, 0) -->
    <axis xyz="0 1 0"/>
  </joint>

  <!-- Small roller 17 (α = 306°: y ≈ 0.0470,  z ≈ –0.0647) -->
  <link name="OmniFR_roller_17">
    <collision>
      <origin xyz="0 0 0" rpy="0 0 0"/>
      <geometry>
        <sphere radius="0.015"/>
      </geometry>
    </collision>
    <inertial>
      <mass value="0.5"/>
      <inertia
        ixx="0.00000018" ixy="0.0" ixz="0.0"
        iyy="0.00000018" iyz="0.0"
        izz="0.00000018"/>
    </inertial>
  </link>
  <joint name="OmniFR_roller_17_joint" type="continuous">
    <parent link="OmniFR_wheel"/>
    <child  link="OmniFR_roller_17"/>
    <origin xyz="0 0.0470 -0.0647" rpy="0 0 0"/>
    <!-- axis = (0, –sin306°, cos306°) = (0, 0.809, 0.588) -->
    <axis xyz="0 0.809 0.588"/>
  </joint>

  <!-- Small roller 19 (α = 342°: y ≈ 0.0761,  z ≈ –0.0247) -->
  <link name="OmniFR_roller_19">
    <collision>
      <origin xyz="0 0 0" rpy="0 0 0"/>
      <geometry>
        <sphere radius="0.015"/>
      </geometry>
    </collision>
    <inertial>
      <mass value="0.5"/>
      <inertia
        ixx="0.00000018" ixy="0.0" ixz="0.0"
        iyy="0.00000018" iyz="0.0"
        izz="0.00000018"/>
    </inertial>
  </link>
  <joint name="OmniFR_roller_19_joint" type="continuous">
    <parent link="OmniFR_wheel"/>
    <child  link="OmniFR_roller_19"/>
    <origin xyz="0 0.0761 -0.0247" rpy="0 0 0"/>
    <!-- axis = (0, –sin342°, cos342°) = (0, 0.309, 0.951) -->
    <axis xyz="0 0.309 0.951"/>
  </joint>




<!--- ARM1, RIGHT SLAVE-->
   <joint name="arm1_base_joint" type="fixed">
    <parent link="base_link"/>
    <child link="arm1_base_link"/>
    <origin xyz="0 0 0" rpy="0 0 0"/>
    <!-- <origin xyz="-0.095 0  0.579" rpy="0 0 0"/> -->
    <!-- <origin xyz="-0.095 -0.135470  0.623356" rpy="0.174533 0 0"/> -->
  </joint>

  <link name="arm1_base_link">
      <inertial>
            <origin xyz="0 0 0" rpy="0 0 0" />
            <mass value="0.641" />
            <inertia ixx="0.00008" ixy="0.00000" ixz="0.00001" iyy="0.00003" iyz="0.00000" izz="0.00007" />
    </inertial>
    <visual>
      <origin rpy="0 0 0" xyz="0 0 0"/>
      <geometry>
        <mesh filename="/root/IsaacLab/anubis/meshes/arm_base_link.stl"/>
      </geometry>
      <material name="">
        <color rgba="0.75294 0.75294 0.75294 1"/>
      </material>
    </visual>
    <collision>
      <origin rpy="0 0 0" xyz="0 0 0"/>
      <geometry>
        <mesh filename="/root/IsaacLab/anubis/meshes/arm_base_link.stl"/>
      </geometry>
    </collision>
  </link>

  <joint name="arm1_base_link_joint" type="revolute">
    <parent link="arm1_base_link"/>
    <child link="link11"/>
    <origin xyz="-0.095 -0.135470  0.82335578" rpy="0.174533 0 0"/>
    <axis xyz="0 0 1"/>
    <limit effort="3" lower="-0.523599" upper=" 0.523599" velocity="1.3963"/>
  </joint>
  <link name="link11">
    <inertial>
            <origin xyz="0 0 0" rpy="0 0 0" />
            <mass value="0.400" />
            <inertia ixx="0.00008" ixy="0.00000" ixz="0.00001" iyy="0.00003" iyz="0.00000" izz="0.00007" />
    </inertial>
    <visual>
      <origin rpy="0 0 0" xyz="0 0 0"/>
      <geometry>
        <mesh filename="/root/IsaacLab/anubis/meshes/link1.stl"/>
      </geometry>
      <material name="">
        <color rgba="0.75294 0.75294 0.75294 1"/>
      </material>
    </visual>
    <collision>
      <origin rpy="0 0 0" xyz="0 0 0"/>
      <geometry>
         <mesh filename="/root/IsaacLab/anubis/meshes/link1.stl"/>
      </geometry>
    </collision>
  </link>

  <joint name="link11_joint" type="revolute">
    <parent link="link11"/>
    <child link="link12"/>
    <origin rpy="0 0 0" xyz="0 0 0.062"/>
    <axis xyz="0 1 0"/>
    <limit effort="3" lower="-0.74533" upper="1.91986" velocity="1.3963"/>
  </joint>
  <link name="link12">
        <inertial>
            <origin xyz="0 0 0" rpy="0 0 0" />
            <mass value="0.30" />
            <inertia ixx="0.00008" ixy="0.00000" ixz="0.00001" iyy="0.00003" iyz="0.00000" izz="0.00007" />
    </inertial>
    <visual>
      <origin rpy="0 0 0" xyz="0 0 -0.062"/>
      <geometry>
        <mesh filename="/root/IsaacLab/anubis/meshes/link2.stl"/>
      </geometry>
      <material name="">
        <color rgba="0.75294 0.75294 0.75294 1"/>
      </material>
    </visual>  
    <collision>
      <origin rpy="0 0 0" xyz="0 0 -0.062"/>
      <geometry>
        <mesh filename="/root/IsaacLab/anubis/meshes/link2.stl"/>
      </geometry>
    </collision>
  </link>
  <joint name="link12_joint" type="revolute">
    <parent link="link12"/>
    <child link="link13"/>
    <origin rpy="0 0 0" xyz="0 0 0.3"/>
    <axis xyz="0 1 0"/>
    <limit effort="3" lower="-0.174533" upper="2.79253" velocity="1.3963"/>
  </joint>
  <link name="link13">
    <inertial>
            <origin xyz="0 0 0" rpy="0 0 0" />
            <mass value="	0.400" />
            <inertia ixx="0.00008" ixy="0.00000" ixz="0.00001" iyy="0.00003" iyz="0.00000" izz="0.00007" />
    </inertial>
    <visual>
      <origin rpy="0 0 0" xyz="0 0 -0.362"/>
      <geometry>
        <mesh filename="/root/IsaacLab/anubis/meshes/link3.stl"/>
      </geometry>
      <material name="">
        <color rgba="0.75294 0.75294 0.75294 1"/>
      </material>
    </visual>
    <collision>
      <origin rpy="0 0 0" xyz="0 0 -0.362"/>
      <geometry>
        <mesh filename="/root/IsaacLab/anubis/meshes/link3.stl"/>
      </geometry>
    </collision>
  </link>

  <joint name="link13_joint" type="revolute">
    <parent link="link13"/>
    <child link="link14"/>
    <origin rpy="0 0 0" xyz="0 0 0.32"/>
    <axis xyz="0 1 0"/>
    <limit effort="3" lower="-1.5708" upper="1.74533" velocity="1.3963"/>
  </joint>

  <link name="link14">
    <inertial>
            <origin xyz="0 0 0" rpy="0 0 0" />
            <mass value="0.300" />
            <inertia ixx="0.00008" ixy="0.00000" ixz="0.00001" iyy="0.00003" iyz="0.00000" izz="0.00007" />
    </inertial>
    <visual>
      <origin rpy="0 0 0" xyz="0 0 -0.662"/>
      <geometry>
        <mesh filename="/root/IsaacLab/anubis/meshes/link4.stl"/>
      </geometry>
      <material name="">
        <color rgba="0.75294 0.75294 0.75294 1"/>
      </material>
    </visual>
    <collision>
      <origin rpy="0 0 0" xyz="0 0 -0.662"/>
      <geometry>
        <mesh filename="/root/IsaacLab/anubis/meshes/link4.stl"/>
      </geometry>
    </collision>
  </link>
  
  <joint name="link14_joint" type="revolute">
    <parent link="link14"/>
    <child link="link15"/>
    <origin rpy="0 0 0" xyz="0 0 0.04"/>
    <axis xyz="-1 0 0"/>
    <limit effort="3" lower="-1.5708" upper="1.57085" velocity="1.3963"/>
  </joint>

  <link name="link15">
    <inertial>
            <origin xyz="0 0 0" rpy="0 0 0" />
            <mass value="0.400" />
            <inertia ixx="0.00008" ixy="0.00000" ixz="0.00001" iyy="0.00003" iyz="0.00000" izz="0.00007" />
    </inertial>
    <visual>
      <origin rpy="0 0 0" xyz="0 0 -0.702"/>
      <geometry>
        <mesh filename="/root/IsaacLab/anubis/meshes/link5.stl"/>
      </geometry>
      <material name="">
        <color rgba="0.75294 0.75294 0.75294 1"/>
      </material>
    </visual>
     <collision>
       <origin rpy="0 0 0" xyz="0 0 -0.702"/>
       <geometry>
         <mesh filename="/root/IsaacLab/anubis/meshes/link5.stl"/>
       </geometry>
     </collision>
  </link>
  
  <joint name="link15_joint" type="revolute">
    <parent link="link15"/>
    <child link="gripper_base_link"/>
    <origin rpy="0 0 -1.57" xyz="0 0 0.027"/>
    <axis xyz="0 0 1"/>
    <limit effort="3" lower="-1.74533" upper="1.74533" velocity="1.3963"/>
  </joint>
  <!--- gripper1-->
  <link name="gripper_base_link" >
    <inertial>
            <origin xyz="0 0 0" rpy="0 0 0" />
            <mass value="0.400" />
            <inertia ixx="0.00008" ixy="0.00000" ixz="0.00001" iyy="0.00003" iyz="0.00000" izz="0.00007" />
    </inertial>
    <visual>
      <origin rpy="0 0 0" xyz="0.0 0 0"/>
      <geometry>
        <mesh filename="/root/IsaacLab/anubis/meshes/gripper/gripper_base_link.stl"/>
      </geometry>
      <material name="">
        <color rgba="0.75294 0.75294 0.75294 1"/>
      </material>
    </visual>
    <collision>
      <origin rpy="0 0 0" xyz="0.0 0 0"/>
      <geometry>
        <mesh filename="/root/IsaacLab/anubis/meshes/gripper/gripper_base_link.stl"/>
      </geometry>
    </collision>
  </link>


	<joint name="ee_fixed_joint1" type="fixed">
	  <parent link="gripper_base_link"/>
	  <child link="ee_link1"/>
	  <origin xyz="0 0  0.13956" rpy="0 0 0"/>
	</joint>
  <link name="ee_link1"/>


  <joint name="gripper1_joint" type="prismatic">
    <parent link="gripper_base_link"/>
    <child link="gripper1L"/>
    <origin rpy="0 0 0" xyz="0 0 0"/>
    <axis xyz="-1 0 0"/>
    <limit velocity="4.8" effort="4" lower="0" upper="0.04" />
  </joint>
  
  <link name="gripper1L" >
	<inertial>
  		<!-- Inertial frame at link origin -->
		<origin xyz="0 0 0" rpy="0 0 0"/>
		<!-- Mass of the gripper -->
  		<mass value="0.35"/>
  		<!-- Moments of inertia about the link frame axes -->
  		<inertia 
    			ixx="0.000347" ixy="0.0"    ixz="0.0"
			iyy="0.000561" iyz="0.0"
			izz="0.000771"/>
	</inertial>
    <visual>
      <origin rpy="0 0 0" xyz="0 0 0"/>
      <geometry>
        <mesh filename="/root/IsaacLab/anubis/meshes/gripper/fingerL.stl"/>
      </geometry>
      <material name="">
        <color rgba="0.75294 0.0 0.0 1"/>
      </material>
    </visual>
    <collision>
      <origin rpy="0 0 0" xyz="-0.00861 0.0005 0.11054"/>
      <geometry>
        <box size="0.018 0.035 0.093"/>
      </geometry>
      <contact_coefficients mu="1.15"  kp="50000.0"  kd="100.0" />
    </collision>
  </link>

  <joint name="gripper1R_joint" type="prismatic">
    <parent link="gripper_base_link"/>
    <child link="gripper1R"/>
    <origin rpy="0 0 0" xyz="0 0 0"/>
    <axis xyz="1 0 0"/>
    <limit velocity="4.8" effort="4" lower="0" upper="0.04" />
  </joint>

  <link name="gripper1R" >
	<inertial>
                <!-- Inertial frame at link origin -->
                <origin xyz="0 0 0" rpy="0 0 0"/>
                <!-- Mass of the gripper -->
                <mass value="0.35"/>
                <!-- Moments of inertia about the link frame axes -->
                <inertia 
                        ixx="0.000347" ixy="0.0"    ixz="0.0"
                        iyy="0.000561" iyz="0.0"
                        izz="0.000771"/>
	</inertial>
	  <visual>
      <origin rpy="0 0 0" xyz="0 0 0"/>
      <geometry>
        <mesh filename="/root/IsaacLab/anubis/meshes/gripper/fingerR.stl"/>
      </geometry>
      <material name="">
        <color rgba="0.75294 0.0 0.0 1"/>
      </material>
    </visual>
    <collision>
      <origin rpy="0 0 0" xyz="0.01061 0.0005 0.11054"/>
      <geometry>
        <box size="0.018 0.035 0.093"/>
      </geometry>
      <contact_coefficients mu="1.15"  kp="50000.0"  kd="100.0" />
    </collision>
  </link>


<!--- ARM2, LEFT SLAVE-->
  <joint name="arm2_base_joint" type="fixed">
    <parent link="base_link"/>
    <child link="arm2_base_link"/>
    <!-- <origin xyz="-0.095 0.135470  0.623356" rpy="0.174533 0 3.141592"/> -->
    <!-- <origin xyz="-0.095 0.135470  0.623356" rpy="-0.174533 0 0"/> -->
  </joint>


  <link name="arm2_base_link">
        <inertial>
            <origin xyz="0 0 0" rpy="0 0 0" />
            <mass value="0.641" />
            <inertia ixx="0.00008" ixy="0.00000" ixz="0.00001" iyy="0.00003" iyz="0.00000" izz="0.00007" />
    </inertial>
    <visual>
      <origin rpy="0 0 3.14159" xyz="-0.19 0 0"/>
      <geometry>
        <mesh filename="/root/IsaacLab/anubis/meshes/arm_base_link.stl"/>
      </geometry>
      <material name="">
      <color rgba="0.75294 0.75294 0.75294 1"/>
    </material>
    </visual>
    <collision> 
      <origin rpy="0 0 3.14159" xyz="-0.19 0 0"/>
      <geometry>
        <mesh filename="/root/IsaacLab/anubis/meshes/arm_base_link.stl"/>
      </geometry>
    </collision>
  </link>
  
  <joint name="arm2_base_link_joint" type="revolute">
    <parent link="arm2_base_link"/>
    <child link="link21"/>
    <origin xyz="-0.095 0.135470  0.82335578" rpy="0.174533 0 3.14159"/>
    <axis xyz="0 0 1"/>
    <limit effort="3" lower="-0.523599" upper="0.523599" velocity="1.3963"/>
  </joint>
  
  <link name="link21">
    <inertial>
            <origin xyz="0 0 0" rpy="0 0 0" />
            <mass value="	0.400" />
            <inertia ixx="0.00008" ixy="0.00000" ixz="0.00001" iyy="0.00003" iyz="0.00000" izz="0.00007" />
    </inertial>
    <visual>
      <origin rpy="0 0 0" xyz="0 0 0"/>
      <geometry>
        <mesh filename="/root/IsaacLab/anubis/meshes/link1.stl"/>
      </geometry>
      <material name="">
        <color rgba="0.75294 0.75294 0.75294 1"/>
      </material>
    </visual>
    <collision> 
      <origin rpy="0 0 0" xyz="0 0 0"/>
      <geometry>
        <mesh filename="/root/IsaacLab/anubis/meshes/link1.stl"/>
      </geometry>
    </collision>
  </link>

  <joint name="link21_joint" type="revolute">
    <parent link="link21"/>
    <child link="link22"/>
    <origin rpy="0 0 0" xyz="0 0 0.062"/>
    <axis xyz="0 -1 0"/>
    <limit effort="3" lower="-0.74533" upper="1.91986" velocity="1.3963"/>
  </joint>
  
  <link name="link22">
      <inertial>
            <origin xyz="0 0 0" rpy="0 0 0" />
            <mass value="0.30" />
            <inertia ixx="0.00008" ixy="0.00000" ixz="0.00001" iyy="0.00003" iyz="0.00000" izz="0.00007" />
    </inertial>
    <visual>
      <origin rpy="0 0 0" xyz="0 0 -0.062"/>
      <geometry>
        <mesh filename="/root/IsaacLab/anubis/meshes/link2.stl"/>
      </geometry>
      <material name="">
        <color rgba="0.75294 0.75294 0.75294 1"/>
      </material>
    </visual>
    <collision> 
      <origin rpy="0 0 0" xyz="0 0 -0.062"/>
      <geometry>
        <mesh filename="/root/IsaacLab/anubis/meshes/link2.stl"/>
      </geometry>
    </collision>
  </link>
  
  <joint name="link22_joint" type="revolute">
    <parent link="link22"/>
    <child link="link23"/>
    <origin rpy="0 0 0" xyz="0 0 0.3"/>
    <axis xyz="0 -1 0"/>
    <limit effort="3" lower="-0.174533" upper="2.79253" velocity="1.3963"/>
  </joint>

  <link name="link23">
    <inertial>
            <origin xyz="0 0 0" rpy="0 0 0" />
            <mass value="	0.400" />
            <inertia ixx="0.00008" ixy="0.00000" ixz="0.00001" iyy="0.00003" iyz="0.00000" izz="0.00007" />
    </inertial>
    <visual>
      <origin rpy="0 0 0" xyz="0 0 -0.362"/>
      <geometry>
        <mesh filename="/root/IsaacLab/anubis/meshes/link3.stl"/>
      </geometry>
      <material name="">
        <color rgba="0.75294 0.75294 0.75294 1"/>
      </material>
    </visual>
    <collision> 
      <origin rpy="0 0 0" xyz="0 0 -0.362"/>
      <geometry>
        <mesh filename="/root/IsaacLab/anubis/meshes/link3.stl"/>
      </geometry>
    </collision>
  </link>

  <joint name="link23_joint" type="revolute">
    <parent link="link23"/>
    <child link="link24"/>
    <origin rpy="0 0 3.14159" xyz="0 0 0.32"/>
    <axis xyz="0 1 0"/>
    <limit effort="3" lower="-1.5708" upper="1.74533" velocity="1.3963"/>
  </joint>
  
  <link name="link24">
    <inertial>
            <origin xyz="0 0 0" rpy="0 0 0" />
            <mass value="0.300" />
            <inertia ixx="0.00008" ixy="0.00000" ixz="0.00001" iyy="0.00003" iyz="0.00000" izz="0.00007" />
    </inertial>
    <visual>
      <origin rpy="0 0 0" xyz="0 0 -0.662"/>
      <geometry>
        <mesh filename="/root/IsaacLab/anubis/meshes/link4.stl"/>
      </geometry>
      <material name="">
        <color rgba="0.75294 0.75294 0.75294 1"/>
      </material>
    </visual>
    <collision> 
      <origin rpy="0 0 0" xyz="0 0 -0.662"/>
      <geometry>
        <mesh filename="/root/IsaacLab/anubis/meshes/link4.stl"/>
      </geometry>
    </collision>
  </link>
  <joint name="link24_joint" type="revolute">
    <parent link="link24"/>
    <child link="link25"/>
    <origin rpy="0 0 0" xyz="0 0 0.04"/>
    <axis xyz="-1 0 0"/>
    <limit effort="3" lower="-1.5708" upper="1.5708" velocity="1.3963"/>
  </joint>
  <link name="link25">
    <inertial>
            <origin xyz="0 0 0" rpy="0 0 0" />
            <mass value="0.400" />
            <inertia ixx="0.00008" ixy="0.00000" ixz="0.00001" iyy="0.00003" iyz="0.00000" izz="0.00007" />
    </inertial>
    <visual>
      <origin rpy="0 0 0" xyz="0 0 -0.702"/>
      <geometry>
        <mesh filename="/root/IsaacLab/anubis/meshes/link5.stl"/>
      </geometry>
      <material name="">
        <color rgba="0.75294 0.75294 0.75294 1"/>
      </material>
    </visual>
    <collision>
      <origin rpy="0 0 0" xyz="0 0 -0.702"/>
       <geometry>
         <mesh filename="/root/IsaacLab/anubis/meshes/link5.stl"/>
       </geometry>
    </collision>
  </link>

  <joint name="link25_joint" type="revolute">
    <parent link="link25"/>
    <child link="gripper2_base_link"/>
    <origin rpy="0 0 -1.57" xyz="0 0 0.027"/>
    <axis xyz="0 0 1"/>
    <limit effort="3" lower="-1.74533" upper="1.74533" velocity="1.3963"/>
  </joint>

  <link name="gripper2_base_link" >
    <inertial>
            <origin xyz="0 0 0" rpy="0 0 0" />
            <mass value="0.400" />
            <inertia ixx="0.00008" ixy="0.00000" ixz="0.00001" iyy="0.00003" iyz="0.00000" izz="0.00007" />
    </inertial>
    <visual>
      <origin rpy="0 0 0" xyz="0.0 0 0"/>
      <geometry>
        <mesh filename="/root/IsaacLab/anubis/meshes/gripper/gripper_base_link.stl"/>
      </geometry>
      <material name="">
        <color rgba="0.75294 0.75294 0.75294 1"/>
      </material>
    </visual>
    <collision> 
      <origin rpy="0 0 0" xyz="0.0 0 0"/>
      <geometry>
        <mesh filename="/root/IsaacLab/anubis/meshes/gripper/gripper_base_link.stl"/>
      </geometry>
    </collision>
  </link>

	<joint name="ee_fixed_joint2" type="fixed">
	  <parent link="gripper2_base_link"/>
	  <child link="ee_link2"/>
	  <origin xyz="0 0 0.13956" rpy="0 0 0"/>
	</joint>
  <link name="ee_link2"/>
  <joint name="gripper2_joint" type="prismatic">
    <parent link="gripper2_base_link"/>
    <child link="gripper2L"/>
    <origin rpy="0 0 0" xyz="0 0 0"/>
    <axis xyz="-1 0 0"/>
    <limit velocity="4.8" effort="4" lower="0" upper="0.04" />
  </joint>
  <link name="gripper2L" >
        <inertial>
                <!-- Inertial frame at link origin -->
                <origin xyz="0 0 0" rpy="0 0 0"/>
                <!-- Mass of the gripper -->
                <mass value="0.35"/>
                <!-- Moments of inertia about the link frame axes -->
                <inertia 
                        ixx="0.000347" ixy="0.0"    ixz="0.0"
                        iyy="0.000561" iyz="0.0"
                        izz="0.000771"/>
        </inertial>      
	  <visual>
      <origin rpy="0 0 0" xyz="0 0 0"/>
      <geometry>
        <mesh filename="/root/IsaacLab/anubis/meshes/gripper/fingerL.stl"/>
      </geometry>
      <material name="">
        <color rgba="0.75294 0.0 0.0 1"/>
      </material>
    </visual>
    <collision>
      <origin rpy="0 0 0" xyz="-0.00861 0.0005 0.11054"/>
      <geometry>
        <box size="0.018 0.035 0.093"/>
      </geometry>
      <contact_coefficients mu="1.15"  kp="50000.0"  kd="100.0" />
    </collision>
  </link>

  <joint name="gripper2R_joint" type="prismatic">
    <parent link="gripper2_base_link"/>
    <child link="gripper2R"/>
    <origin rpy="0 0 0" xyz="0 0 0"/>
    <axis xyz="1 0 0"/>
    <limit velocity="4.8" effort="4" lower="0" upper="0.04" />
  </joint>
  <link name="gripper2R" >
	          <inertial>
                <!-- Inertial frame at link origin -->
                <origin xyz="0 0 0" rpy="0 0 0"/>
                <!-- Mass of the gripper -->
                <mass value="0.35"/>
                <!-- Moments of inertia about the link frame axes -->
                <inertia 
                        ixx="0.000347" ixy="0.0"    ixz="0.0"
                        iyy="0.000561" iyz="0.0"
                        izz="0.000771"/>
        </inertial>
	  <visual>
      <origin rpy="0 0 0" xyz="0 0 0"/>
      <geometry>
        <mesh filename="/root/IsaacLab/anubis/meshes/gripper/fingerR.stl"/>
      </geometry>
      <material name="">
        <color rgba="0.75294 0.0 0.0 1"/>
      </material>
    </visual>
    <collision>                               
      <origin rpy="0 0 0" xyz="0.00828 0.00079 0.1109"/>
      <geometry>
        <box size="0.018 0.035 0.093"/>
      </geometry>
      <contact_coefficients mu="1.15"  kp="50000.0"  kd="100.0" />
    </collision>
  </link>
</robot>
